<?xml version='1.0' encoding='utf-8'?>
<mujoco model="urdf">
  <compiler angle="radian" />
  <asset>
    <mesh name="robstrideo0" file="assets/robstrideo0.stl" />
    <mesh name="torso22" file="assets/torso22.stl" />
    <mesh name="torso12" file="assets/torso12.stl" />
    <mesh name="hipz12" file="assets/hipz12.stl" />
    <mesh name="robstride02" file="assets/robstride02.stl" />
    <mesh name="hipz22" file="assets/hipz22.stl" />
    <mesh name="hipxy" file="assets/hipxy.stl" />
    <mesh name="knee_rod22" file="assets/knee_rod22.stl" />
    <mesh name="robstrideo3" file="assets/robstrideo3.stl" />
    <mesh name="knee_rod12" file="assets/knee_rod12.stl" />
    <mesh name="femur_22" file="assets/femur_22.stl" />
    <mesh name="femur_12" file="assets/femur_12.stl" />
    <mesh name="hat_femur" file="assets/hat_femur.stl" />
    <mesh name="part_3" file="assets/part_3.stl" />
    <mesh name="rmdx43" file="assets/rmdx43.stl" />
    <mesh name="tibias22" file="assets/tibias22.stl" />
    <mesh name="actuation_ankle" file="assets/actuation_ankle.stl" />
    <mesh name="tibias12" file="assets/tibias12.stl" />
    <mesh name="ujoint" file="assets/ujoint.stl" />
    <mesh name="spacer_ujoint" file="assets/spacer_ujoint.stl" />
    <mesh name="hat_small" file="assets/hat_small.stl" />
    <mesh name="foot" file="assets/foot.stl" />
    <mesh name="hipz22_sym" file="assets/hipz22_sym.stl" />
    <mesh name="hipz12_sym" file="assets/hipz12_sym.stl" />
    <mesh name="hipxy_sym" file="assets/hipxy_sym.stl" />
    <mesh name="knee_rod22_sym" file="assets/knee_rod22_sym.stl" />
    <mesh name="femur_12_sym" file="assets/femur_12_sym.stl" />
    <mesh name="femur_22_sym" file="assets/femur_22_sym.stl" />
    <mesh name="knee_rod12_sym" file="assets/knee_rod12_sym.stl" />
    <mesh name="tibias12_sym" file="assets/tibias12_sym.stl" />
    <mesh name="tibias22_sym" file="assets/tibias22_sym.stl" />
    <mesh name="torso_meshe" file="assets/torso_meshe.stl" />
  </asset>

  <worldbody>
    <body name="base" pos="0 0 0.72">
      <joint name="root" type="free" />
      <geom pos="-0.673363 0.0109625 0.061034" quat="0.707105 0.707108 0 0" type="mesh" rgba="0.301961 0.301961 0.301961 1" mesh="robstrideo0" />
      <geom pos="-0.000263039 0.233572 -0.0901625" quat="1.86697e-07 -1.31359e-06 0.99005 -0.140713" type="mesh" rgba="1 0 0 1" mesh="torso22" />
      <geom pos="0.672086 -0.147255 0.0629195" quat="0.00131867 -0.00114353 -0.655473 -0.755216" type="mesh" rgba="0.301961 0.301961 0.301961 1" mesh="robstrideo0" />
      <geom pos="0.672086 0.12555 0.0660044" quat="-0.00114353 0.00131866 0.755219 0.65547" type="mesh" rgba="0.301961 0.301961 0.301961 1" mesh="robstrideo0" />
      <geom pos="-0.000263039 4.05842e-07 -0.056966" quat="1.75787e-12 1.32679e-06 1 1.32679e-06" type="mesh" rgba="1 0 0 1" mesh="torso12" />
      <geom pos="-0.000263039 4.05842e-07 -0.056966" quat="1.75793e-12 1.32679e-06 1 1.32679e-06" type="mesh" rgba="1 0 0 1" mesh="torso22" />
      <geom pos="0.025 0.503548 0.0499987" quat="-1 2.65359e-06 0 0" type="mesh" rgba="0.301961 0.301961 0.301961 1" mesh="torso_meshe" />
      <body name="hipx_subassembly" pos="-0.000819037 -0.133159 0.04164" quat="0.821909 0.0571232 0.0414079 -0.565233">
        <inertial pos="-0.0179437 -0.0274254 -0.0837243" quat="0.401109 0.424615 -0.783452 0.212171" mass="0.794013" diaginertia="0.00115064 0.000967835 0.000726741" />
        <joint name="hipz_right" pos="0 0 0" axis="0 0 1" range="-3.14159 3.14159" actuatorfrcrange="-10 10" />
        <geom pos="0 0 -0.1" quat="1.32679e-06 -1 0 0" type="mesh" rgba="1 0 0 1" mesh="hipz12" />
        <geom pos="-0.575896 0.0494047 -0.172196" quat="0.792907 -0.60316 -0.052417 -0.0689069" type="mesh" rgba="0.301961 0.301961 0.301961 1" mesh="robstride02" />
        <geom pos="0 0 -0.1" quat="1.32679e-06 -1 0 0" type="mesh" rgba="1 0 0 1" mesh="hipz22" />
        <body name="hipy_subassembly" pos="-0.01897 -0.0289 -0.09689" quat="0.388857 0.132751 0.0879726 -0.907429">
          <inertial pos="0.00476547 -0.00266343 -0.0607297" quat="0.916918 -0.328471 -0.0265972 0.225082" mass="0.241618" diaginertia="0.000514846 0.000474201 0.00039973" />
          <joint name="hipx_right" pos="0 0 0" axis="0 0 1" range="-3.14159 3.14159" actuatorfrcrange="-10 10" />
          <geom type="mesh" rgba="1 0 0 1" mesh="hipxy" />
          <body name="tigh_subassembly" pos="0.012638 -0.0276823 -0.112055" quat="0.289458 0.00726303 0.73048 -0.618515">
            <inertial pos="0.0501976 0.0785779 -0.0353813" quat="0.64331 0.334215 -0.585819 0.362311" mass="2.5804" diaginertia="0.0237789 0.0223377 0.0035913" />
            <joint name="hipy_right" pos="0 0 0" axis="0 0 1" range="-3.14159 3.14159" actuatorfrcrange="-10 10" />
            <geom pos="0.210506 0.184547 -0.0305" quat="0.612371 0.612373 -0.353555 -0.353553" type="mesh" rgba="0.917647 0.917647 0.917647 1" mesh="knee_rod22" />
            <geom pos="-0.437806 0.570998 -0.07" quat="0.683011 -0.683014 0.183013 -0.183012" type="mesh" rgba="0.301961 0.301961 0.301961 1" mesh="robstrideo3" />
            <geom pos="0.210506 0.184547 -0.0305" quat="0.612371 0.612373 -0.353555 -0.353553" type="mesh" rgba="0.917647 0.917647 0.917647 1" mesh="knee_rod12" />
            <geom pos="0.17 0.294449 -0.0305" quat="0.683011 0.683014 -0.183013 -0.183012" type="mesh" rgba="1 0 0 1" mesh="femur_22" contype="1" conaffinity="1" />
            <geom pos="0.17 0.294449 -0.0305" quat="0.683011 0.683014 -0.183013 -0.183012" type="mesh" rgba="1 0 0 1" mesh="femur_12" contype="1" conaffinity="1" />
            <geom pos="0.17 0.294449 -0.0305" quat="0.683011 0.683014 -0.183013 -0.183012" type="mesh" rgba="1 0 0 1" mesh="hat_femur" />
            <geom pos="0 0 -0.0938" quat="0.183014 -0.683011 0.183014 0.683014" type="mesh" rgba="1 0 0 1" mesh="part_3" />
            <geom pos="-0.495806 0.470539 -0.0275" quat="0.683011 -0.683014 0.183013 -0.183012" type="mesh" rgba="0.301961 0.301961 0.301961 1" mesh="robstrideo3" />
            <body name="shin_subassembly" pos="0.17 0.294449 -0.0305" quat="1.27794e-06 0.963177 -0.26887 -3.56735e-07">
              <inertial pos="-0.076547 -0.0486454 6.35117e-05" quat="-0.212792 0.669636 0.143815 0.696868" mass="0.593267" diaginertia="0.00177092 0.00174055 0.000241288" />
              <joint name="knee_right" pos="0 0 0" axis="0 0 1" range="-3.14159 3.14159" actuatorfrcrange="-10 10" />
              <geom pos="-0.2967 0.369726 0.019" quat="0.616798 0.6168 -0.345774 -0.345773" type="mesh" rgba="0.301961 0.301961 0.301961 1" mesh="rmdx43" />
              <geom pos="-0.221803 -0.135659 0.019" quat="0.616798 -0.6168 0.345774 -0.345773" type="mesh" rgba="1 0 0 1" mesh="tibias22" />
              <geom pos="-0.0303217 0.125625 -0.019" quat="0.706277 0.706279 -0.0342294 -0.0342292" type="mesh" rgba="0.917647 0.917647 0.917647 1" mesh="actuation_ankle" />
              <geom pos="-0.341913 0.342073 0.006" quat="0.616798 0.6168 -0.345774 -0.345773" type="mesh" rgba="0.301961 0.301961 0.301961 1" mesh="rmdx43" />
              <geom pos="-0.221803 -0.135659 0.019" quat="0.616798 -0.6168 0.345774 -0.345773" type="mesh" rgba="1 0 0 1" mesh="tibias12" />
              <geom pos="-0.105319 -0.208585 0.019" quat="0.706277 -0.706279 0.0342294 -0.0342292" type="mesh" rgba="0.917647 0.917647 0.917647 1" mesh="actuation_ankle" />
              <body name="ankle_subassembly" pos="-0.221803 -0.135659 0.02" quat="1.10817e-06 -0.835222 -0.549913 7.29622e-07">
                <inertial pos="-1.62086e-08 -0.000727483 0.02" mass="0.0168168" diaginertia="5.19458e-06 4.86353e-06 8.35665e-07" />
                <joint name="ankley_right" pos="0 0 0" axis="0 0 1" range="-3.14159 3.14159" actuatorfrcrange="-10 10" />
                <geom pos="0 0 0.02" quat="9.38184e-07 0.707105 9.38187e-07 -0.707108" type="mesh" rgba="1 0 0 1" mesh="ujoint" />
                <geom pos="0 0 0.02" quat="0.71462 0 -0.699512 0" type="mesh" rgba="0.917647 0.917647 0.917647 1" mesh="spacer_ujoint" />
                <geom pos="0 0 0.0195" quat="9.38184e-07 0.707105 9.38187e-07 -0.707108" type="mesh" rgba="1 0 0 1" mesh="part_3" />
                <geom pos="0 0 0.0205" quat="9.38184e-07 -0.707105 -9.38187e-07 -0.707108" type="mesh" rgba="1 0 0 1" mesh="part_3" />
                <geom pos="0 5.64895e-06 0.02" quat="9.45034e-07 0.71227 9.31284e-07 -0.701906" type="mesh" rgba="0.917647 0.917647 0.917647 1" mesh="spacer_ujoint" />
                <body name="foot_subassembly" pos="0 -0.01594 0.02" quat="0.499998 0.5 0.5 -0.500002">
                  <inertial pos="8.52312e-09 -0.0138418 -0.052232" quat="0.705627 0.0421767 -0.042203 0.706067" mass="0.122498" diaginertia="0.000163602 0.000163413 6.9433e-05" />
                  <joint name="anklex_right" pos="0 0 0" axis="0 0 1" range="-3.14159 3.14159" actuatorfrcrange="-10 10" />
                  <geom pos="0 -0.035 -0.0385" quat="0.499998 -0.5 -0.5 -0.500002" type="mesh" rgba="1 0 0 1" mesh="hat_small" />
                  <geom pos="0 -0.035 -0.0385" quat="0.499998 -0.5 -0.5 -0.500002" type="mesh" rgba="0.301961 0.301961 0.301961 1" mesh="foot" contype="1" conaffinity="1" />
                  <geom name="foot_contact_right" type="box" size="0.03 0.02 0.005" pos="0 0 -0.01" rgba="0 0 1 0.3" contype="1" conaffinity="1" />
                </body>
              </body>
            </body>
          </body>
        </body>
      </body>
    <body name="hipx_subassemby_sym" pos="-0.000819037 0.13316 0.04164" quat="0.826606 -0.0574674 0.0409289 0.558341">
        <inertial pos="-0.0179432 0.0274245 -0.0837272" quat="0.424685 0.401162 -0.212175 0.783386" mass="0.794016" diaginertia="0.0011506 0.000967878 0.000726822" />
        <joint name="hipz_left" pos="0 0 0" axis="0 0 1" range="-3.14159 3.14159" actuatorfrcrange="-10 10" />
        <geom pos="-0.575896 0.057308 -0.20175" quat="0.603161 -0.792907 -0.068907 -0.0524169" type="mesh" rgba="0.301961 0.301961 0.301961 1" mesh="robstride02" />
        <geom pos="0 0 0.1" quat="1 0 0 0" type="mesh" rgba="1 0 0 1" mesh="hipz22_sym" />
        <geom pos="0 0 0.1" quat="1 0 0 0" type="mesh" rgba="1 0 0 1" mesh="hipz12_sym" />
        <body name="hipy_subassembly_sym" pos="-0.01897 0.0289 -0.09689" quat="0.378585 -0.131748 0.0894673 0.911763">
          <inertial pos="0.0047654 0.00266393 -0.0607296" quat="0.916914 0.328483 -0.0266015 -0.225077" mass="0.241619" diaginertia="0.000514848 0.000474202 0.000399736" />
          <joint name="hipx_left" pos="0 0 0" axis="0 0 1" range="-3.14159 3.14159" actuatorfrcrange="-10 10" />
          <geom quat="1.32679e-06 1 0 0" type="mesh" rgba="1 0 0 1" mesh="hipxy_sym" />
          <body name="tigh_subassembly_sym" pos="0.012638 0.0276823 -0.112055" quat="-0.0583156 0.358704 0.636384 0.680402">
            <inertial pos="-0.0431321 -0.0830741 -0.0353867" quat="0.584181 0.376186 -0.634805 0.337993" mass="2.5804" diaginertia="0.0240047 0.0225643 0.00359599" />
            <joint name="hipy_left" pos="0 0 0" axis="0 0 1" range="-3.14159 3.14159" actuatorfrcrange="-10 10" />
            <geom pos="-0.058 -0.280519 0.0295" quat="0.707105 -0.707108 0 0" type="mesh" rgba="0.917647 0.917647 0.917647 1" mesh="knee_rod22_sym" />
            <geom pos="0 0 -0.0938" quat="0.683011 0.183012 0.683014 -0.183013" type="mesh" rgba="1 0 0 1" mesh="part_3" />
            <geom pos="-0.17 -0.294449 0.0295" quat="0.683011 -0.683014 0.183013 -0.183012" type="mesh" rgba="1 0 0 1" mesh="femur_12_sym" contype="1" conaffinity="1" />
            <geom pos="-0.17 -0.294449 0.0295" quat="0.683011 -0.683014 0.183013 -0.183012" type="mesh" rgba="1 0 0 1" mesh="femur_22_sym" contype="1" conaffinity="1" />
            <geom pos="-0.17 -0.294449 -0.0305" quat="0.183014 0.183014 0.683014 0.683011" type="mesh" rgba="1 0 0 1" mesh="hat_femur" />
            <geom pos="0.655402 -0.194111 -0.0025" quat="0.183014 0.183014 0.683014 0.683011" type="mesh" rgba="0.301961 0.301961 0.301961 1" mesh="robstrideo3" />
            <geom pos="-0.058 -0.280519 0.0295" quat="0.707105 -0.707108 0 0" type="mesh" rgba="0.917647 0.917647 0.917647 1" mesh="knee_rod12_sym" />
            <geom pos="0.597402 -0.29457 -0.045" quat="0.183014 0.183014 0.683014 0.683011" type="mesh" rgba="0.301961 0.301961 0.301961 1" mesh="robstrideo3" />
            <body name="shin_subassembly_sym" pos="-0.17 -0.294449 -0.0305" quat="0.723236 0 0 -0.690601">
              <inertial pos="0.00133174 -0.0908013 -1.51262e-05" quat="0.516321 0.466893 -0.500826 0.51439" mass="0.593266" diaginertia="0.00176631 0.00174084 0.000233805" />
              <joint name="knee_left" pos="0 0 0" axis="0 0 1" range="-3.14159 3.14159" actuatorfrcrange="-10 10" />
              <geom pos="0 -0.26 0.067" quat="0.707105 -0.707108 0 0" type="mesh" rgba="1 0 0 1" mesh="tibias12_sym" />
              <geom pos="0.12299 -0.14568 0.0195" quat="0.632813 -0.632815 -0.31551 0.315509" type="mesh" rgba="0.917647 0.917647 0.917647 1" mesh="actuation_ankle" />
              <geom pos="0.470217 -0.113201 -0.006" quat="9.38184e-07 -9.38187e-07 0.707108 -0.707105" type="mesh" rgba="0.301961 0.301961 0.301961 1" mesh="rmdx43" />
              <geom pos="0.470217 -0.0457991 0.006" quat="9.38184e-07 9.38187e-07 -0.707108 -0.707105" type="mesh" rgba="0.301961 0.301961 0.301961 1" mesh="rmdx43" />
              <geom pos="0 -0.26 0.067" quat="0.707105 -0.707108 0 0" type="mesh" rgba="1 0 0 1" mesh="tibias22_sym" />
              <geom pos="-0.12299 -0.0133205 -0.0195" quat="0.632813 0.632815 0.31551 0.315509" type="mesh" rgba="0.917647 0.917647 0.917647 1" mesh="actuation_ankle" />
              <body name="ankle_subassembly_2" pos="0 -0.26 -0.02" quat="0.888105 0 0 -0.459641">
                <inertial pos="1.62086e-08 -0.000727483 0.02" mass="0.0168168" diaginertia="5.19458e-06 4.86353e-06 8.35665e-07" />
                <joint name="ankley_left" pos="0 0 0" axis="0 0 1" range="-3.14159 3.14159" actuatorfrcrange="-10 10" />
                <geom pos="0 0 0.02" quat="9.38184e-07 -0.707105 -9.38187e-07 -0.707108" type="mesh" rgba="1 0 0 1" mesh="ujoint" />
                <geom pos="0 0 0.02" quat="0.699512 -2.00452e-08 0.71462 -2.00452e-08" type="mesh" rgba="0.917647 0.917647 0.917647 1" mesh="spacer_ujoint" />
                <geom pos="0 0 0.0205" quat="9.38184e-07 -0.707105 -9.38187e-07 -0.707108" type="mesh" rgba="1 0 0 1" mesh="part_3" />
                <geom pos="0 0 0.0195" quat="9.38184e-07 0.707105 9.38187e-07 -0.707108" type="mesh" rgba="1 0 0 1" mesh="part_3" />
                <geom pos="0 5.64895e-06 0.02" quat="9.45034e-07 0.701906 -9.31284e-07 0.71227" type="mesh" rgba="0.917647 0.917647 0.917647 1" mesh="spacer_ujoint" />
                <body name="foot_subassembly_2" pos="0 -0.01594 0.02" quat="0.50173 0.501732 -0.498262 0.498264">
                  <inertial pos="8.52312e-09 -0.0138418 -0.052232" quat="0.705627 0.0421767 -0.042203 0.706067" mass="0.122498" diaginertia="0.000163602 0.000163413 6.9433e-05" />
                  <joint name="anklex_left" pos="0 0 0" axis="0 0 1" range="-3.14159 3.14159" actuatorfrcrange="-10 10" />
                  <geom pos="0 -0.035 -0.0385" quat="0.499998 -0.5 -0.5 -0.500002" type="mesh" rgba="1 0 0 1" mesh="hat_small" />
                  <geom pos="0 -0.035 -0.0385" quat="0.499998 -0.5 -0.5 -0.500002" type="mesh" rgba="0.301961 0.301961 0.301961 1" mesh="foot" contype="1" conaffinity="1" />
                  <geom name="foot_contact_left" type="box" size="0.03 0.02 0.005" pos="0 0 -0.01" rgba="0 0 1 0.3" contype="1" conaffinity="1" />
                </body>
              </body>
            </body>
          </body>
        </body>
      </body>
    <site name="imu_site" pos="0 0 0" size="0.01" rgba="0 1 0 1" />
    </body>
  </worldbody>
<actuator>
    <position name="m_hipz_right" joint="hipz_right" kp="50" kv="2" gear="1" ctrlrange="-1 1" />
    <position name="m_hipx_right" joint="hipx_right" kp="50" kv="2" gear="1" ctrlrange="-1 1" />
    <position name="m_hipy_right" joint="hipy_right" kp="100" kv="2" gear="1" ctrlrange="-1 1" />
    <position name="m_knee_right" joint="knee_right" kp="100" kv="2" gear="1" ctrlrange="-1 1" />
    <position name="m_ankley_right" joint="ankley_right" kp="40" kv="2" gear="1" ctrlrange="-1 1" />
    <position name="m_anklex_right" joint="anklex_right" kp="10" kv="2" gear="1" ctrlrange="-1 1" />
    <position name="m_hipz_left" joint="hipz_left" kp="50" kv="2" gear="1" ctrlrange="-1 1" />
    <position name="m_hipx_left" joint="hipx_left" kp="50" kv="2" gear="1" ctrlrange="-1 1" />
    <position name="m_hipy_left" joint="hipy_left" kp="100" kv="2" gear="1" ctrlrange="-1 1" />
    <position name="m_knee_left" joint="knee_left" kp="100" kv="2" gear="1" ctrlrange="-1 1" />
    <position name="m_ankley_left" joint="ankley_left" kp="40" kv="2" gear="1" ctrlrange="-1 1" />
    <position name="m_anklex_left" joint="anklex_left" kp="10" kv="2" gear="1" ctrlrange="-1 1" />
  </actuator>
<sensor>
    <jointpos name="q_hipz_right" joint="hipz_right" />
    <jointvel name="qd_hipz_right" joint="hipz_right" />
    <actuatorfrc name="tau_hipz_right" actuator="m_hipz_right" />
    <jointpos name="q_hipx_right" joint="hipx_right" />
    <jointvel name="qd_hipx_right" joint="hipx_right" />
    <actuatorfrc name="tau_hipx_right" actuator="m_hipx_right" />
    <jointpos name="q_hipy_right" joint="hipy_right" />
    <jointvel name="qd_hipy_right" joint="hipy_right" />
    <actuatorfrc name="tau_hipy_right" actuator="m_hipy_right" />
    <jointpos name="q_knee_right" joint="knee_right" />
    <jointvel name="qd_knee_right" joint="knee_right" />
    <actuatorfrc name="tau_knee_right" actuator="m_knee_right" />
    <jointpos name="q_ankley_right" joint="ankley_right" />
    <jointvel name="qd_ankley_right" joint="ankley_right" />
    <actuatorfrc name="tau_ankley_right" actuator="m_ankley_right" />
    <jointpos name="q_anklex_right" joint="anklex_right" />
    <jointvel name="qd_anklex_right" joint="anklex_right" />
    <actuatorfrc name="tau_anklex_right" actuator="m_anklex_right" />
    <jointpos name="q_hipz_left" joint="hipz_left" />
    <jointvel name="qd_hipz_left" joint="hipz_left" />
    <actuatorfrc name="tau_hipz_left" actuator="m_hipz_left" />
    <jointpos name="q_hipx_left" joint="hipx_left" />
    <jointvel name="qd_hipx_left" joint="hipx_left" />
    <actuatorfrc name="tau_hipx_left" actuator="m_hipx_left" />
    <jointpos name="q_hipy_left" joint="hipy_left" />
    <jointvel name="qd_hipy_left" joint="hipy_left" />
    <actuatorfrc name="tau_hipy_left" actuator="m_hipy_left" />
    <jointpos name="q_knee_left" joint="knee_left" />
    <jointvel name="qd_knee_left" joint="knee_left" />
    <actuatorfrc name="tau_knee_left" actuator="m_knee_left" />
    <jointpos name="q_ankley_left" joint="ankley_left" />
    <jointvel name="qd_ankley_left" joint="ankley_left" />
    <actuatorfrc name="tau_ankley_left" actuator="m_ankley_left" />
    <jointpos name="q_anklex_left" joint="anklex_left" />
    <jointvel name="qd_anklex_left" joint="anklex_left" />
    <actuatorfrc name="tau_anklex_left" actuator="m_anklex_left" />
    <gyro name="gyro" site="imu_site" />
    <accelerometer name="accel" site="imu_site" />
    <framequat name="base_quat" body="base" />
    <touch name="touch_right" geom="foot_contact_right" />
    <touch name="touch_left" geom="foot_contact_left" />
  </sensor>
</mujoco>