<mujoco model="urdf">
  <compiler angle="radian"/>

  <asset>
    <mesh name="torso22" content_type="model/stl" file="torso22.stl"/>
    <mesh name="robstrideo0" content_type="model/stl" file="robstrideo0.stl"/>
    <mesh name="torso12" content_type="model/stl" file="torso12.stl"/>
    <mesh name="hipz12" content_type="model/stl" file="hipz12.stl"/>
    <mesh name="robstride02" content_type="model/stl" file="robstride02.stl"/>
    <mesh name="hipz22" content_type="model/stl" file="hipz22.stl"/>
    <mesh name="hipxy" content_type="model/stl" file="hipxy.stl"/>
    <mesh name="knee_rod22" content_type="model/stl" file="knee_rod22.stl"/>
    <mesh name="robstrideo3" content_type="model/stl" file="robstrideo3.stl"/>
    <mesh name="knee_rod12" content_type="model/stl" file="knee_rod12.stl"/>
    <mesh name="bearing_5_16_5" content_type="model/stl" file="bearing_5_16_5.stl"/>
    <mesh name="knee_actuation" content_type="model/stl" file="knee_actuation.stl"/>
    <mesh name="femur_22" content_type="model/stl" file="femur_22.stl"/>
    <mesh name="femur_12" content_type="model/stl" file="femur_12.stl"/>
    <mesh name="hat_femur" content_type="model/stl" file="hat_femur.stl"/>
    <mesh name="part_3" content_type="model/stl" file="part_3.stl"/>
    <mesh name="rmdx43" content_type="model/stl" file="rmdx43.stl"/>
    <mesh name="tibias22" content_type="model/stl" file="tibias22.stl"/>
    <mesh name="actuation_ankle" content_type="model/stl" file="actuation_ankle.stl"/>
    <mesh name="tibias12" content_type="model/stl" file="tibias12.stl"/>
    <mesh name="ujoint" content_type="model/stl" file="ujoint.stl"/>
    <mesh name="spacer_ujoint" content_type="model/stl" file="spacer_ujoint.stl"/>
    <mesh name="hat_small" content_type="model/stl" file="hat_small.stl"/>
    <mesh name="foot" content_type="model/stl" file="foot.stl"/>
    <mesh name="hipz22_sym" content_type="model/stl" file="hipz22_sym.stl"/>
    <mesh name="hipz12_sym" content_type="model/stl" file="hipz12_sym.stl"/>
    <mesh name="hipxy_sym" content_type="model/stl" file="hipxy_sym.stl"/>
    <mesh name="knee_rod22_sym" content_type="model/stl" file="knee_rod22_sym.stl"/>
    <mesh name="femur_12_sym" content_type="model/stl" file="femur_12_sym.stl"/>
    <mesh name="femur_22_sym" content_type="model/stl" file="femur_22_sym.stl"/>
    <mesh name="knee_rod12_sym" content_type="model/stl" file="knee_rod12_sym.stl"/>
    <mesh name="tibias12_sym" content_type="model/stl" file="tibias12_sym.stl"/>
    <mesh name="tibias22_sym" content_type="model/stl" file="tibias22_sym.stl"/>
    <mesh name="torso_meshe" content_type="model/stl" file="torso_meshe.stl"/>
    <mesh name="shoulder1" content_type="model/stl" file="shoulder1.stl"/>
    <mesh name="shoulder2" content_type="model/stl" file="shoulder2.stl"/>
    <mesh name="shoulder1_part" content_type="model/stl" file="shoulder1_part.stl"/>
    <mesh name="shoulder2_part" content_type="model/stl" file="shoulder2_part.stl"/>
    <mesh name="bearing_holder_upperbody" content_type="model/stl" file="bearing_holder_upperbody.stl"/>
    <mesh name="shoulder3_part" content_type="model/stl" file="shoulder3_part.stl"/>
    <mesh name="forarm_part" content_type="model/stl" file="forarm_part.stl"/>
    <mesh name="torso_pperbody_part" content_type="model/stl" file="torso_pperbody_part.stl"/>
  </asset>

  <worldbody>
    <body name="base" pos="0 0 0.72">
    <joint name="root" type="free"/>
     
     
    <geom pos="-0.000261712 0.233572 -0.0901625" quat="1.86697e-07 -1.31359e-06 0.99005 -0.140713" type="mesh" rgba="0.231373 0.380392 0.705882 1" mesh="torso22" />
    <geom pos="0.672087 -0.147255 0.0629195" quat="0.00131867 -0.00114353 -0.655473 -0.755216" type="mesh" rgba="0.231373 0.380392 0.705882 1" mesh="robstrideo0"/>
    <geom pos="0.672087 0.12555 0.0660044" quat="-0.00114353 0.00131866 0.755219 0.65547" type="mesh" rgba="0.231373 0.380392 0.705882 1" mesh="robstrideo0"/>
    <geom pos="-0.000261712 4.03795e-07 -0.056966" quat="1.76037e-12 -1.32679e-06 -1 1.32679e-06" type="mesh" rgba="0.647059 0.647059 0.647059 1" mesh="torso12"/>
    <geom pos="-0.000261712 4.03795e-07 -0.056966" quat="1.76045e-12 -1.32679e-06 -1 1.32679e-06" type="mesh" rgba="0.231373 0.380392 0.705882 1" mesh="torso22"/>
    <geom pos="0.025 0.503548 0.0499987" quat="-1 2.65359e-06 0 0" type="mesh" rgba="0.917647 0.917647 0.917647 1" mesh="torso_meshe"  contype="1" conaffinity="1"/>
    <geom pos="-0.0872593 -0.0522009 0.265098" quat="-0.0848174 -0.417826 -0.264103 0.865146" type="mesh" rgba="0.615686 0.811765 0.929412 1" mesh="shoulder1"/>
    <geom pos="-0.0392561 -0.0511874 0.251582" quat="0.560057 0.0358126 0.597762 -0.57248" type="mesh" rgba="0.615686 0.811765 0.929412 1" mesh="shoulder2"/>
    <geom pos="-0.0076143 0.0907452 0.254464" quat="0.851171 -0.218047 -0.443602 -0.176578" type="mesh" rgba="0.972549 0.529412 0.00392157 1" mesh="shoulder1_part"/>
    <geom pos="0.0145386 -0.0871188 0.209021" quat="-0.334809 -0.934655 0.0492556 0.109069" type="mesh" rgba="0.231373 0.380392 0.705882 1" mesh="shoulder2_part"/>
    <geom pos="-0.0554512 -0.19219 0.091955" quat="0.917449 -0.232744 -0.295007 0.130721" type="mesh" rgba="0.647059 0.647059 0.647059 1" mesh="bearing_holder_upperbody"/>
    <geom pos="0.0106264 -0.0781302 0.265738" quat="-0.701282 -0.487793 -0.400684 0.33123" type="mesh" rgba="0.647059 0.647059 0.647059 1" mesh="bearing_holder_upperbody"/>
    <geom pos="0.191351 0.165659 0.127061" quat="-0.919895 -0.159921 -0.298903 -0.197168" type="mesh" rgba="0.647059 0.647059 0.647059 1" mesh="shoulder3_part"/>
    <geom pos="0.162921 -0.199159 0.121232" quat="0.869203 -0.362747 -0.333087 0.0442065" type="mesh" rgba="0.615686 0.811765 0.929412 1" mesh="forarm_part" contype="1" conaffinity="1"/>
    <geom pos="-0.0205415 4.03795e-07 0.036034" type="mesh" rgba="0.972549 0.529412 0.00392157 1" mesh="torso_pperbody_part"/>
    <geom pos="-0.152957 0.177102 0.327008" quat="-0.295365 -0.95241 0.0361504 0.0660851" type="mesh" rgba="0.647059 0.647059 0.647059 1" mesh="bearing_holder_upperbody"/>
    <geom pos="-0.136588 -0.20345 0.321519" quat="-0.115457 -0.86686 -0.476209 -0.0919186" type="mesh" rgba="0.647059 0.647059 0.647059 1" mesh="bearing_holder_upperbody"/>
    <geom pos="0.191511 0.165136 0.126814" quat="0.245188 -0.920275 -0.0658203 -0.29773" type="mesh" rgba="0.615686 0.811765 0.929412 1" mesh="forarm_part" contype="1" conaffinity="1"/>
    <geom pos="-0.0081198 -0.0903541 0.254198" quat="0.526276 -0.126652 -0.477796 0.691884" type="mesh" rgba="0.972549 0.529412 0.00392157 1" mesh="shoulder1_part"/>
    <geom pos="0.0195138 0.0908249 0.211616" quat="0.409445 -0.910691 -0.0526885 0.0148801" type="mesh" rgba="0.231373 0.380392 0.705882 1" mesh="shoulder2_part"/>
    <geom pos="-0.0221671 0.208312 0.092862" quat="-0.784041 -0.472423 0.392143 0.0912162" type="mesh" rgba="0.647059 0.647059 0.647059 1" mesh="bearing_holder_upperbody"/>
    <geom pos="0.0103965 0.034758 0.220905" quat="-0.211501 -0.845919 -0.475646 -0.115976" type="mesh" rgba="0.647059 0.647059 0.647059 1" mesh="bearing_holder_upperbody"/>
    <geom pos="0.162823 -0.199599 0.121628" quat="-0.287759 -0.850148 0.22524 0.379092" type="mesh" rgba="0.647059 0.647059 0.647059 1" mesh="shoulder3_part"/>
    
    <body name="hipx_subassembly" pos="-0.000819037 -0.133159 0.04164" quat="0.821909 0.0571232 0.0414079 -0.565233">
      <inertial pos="-0.0179437 -0.0274254 -0.0837243" quat="0.401109 0.424615 -0.783452 0.212171" mass="0.794013" diaginertia="0.00115064 0.000967835 0.000726741"/>
      <joint name="hipz_right" pos="0 0 0" axis="0 0 1" range="-3.14159 3.14159" actuatorfrcrange="-10 10"/>
      <geom pos="0 0 -0.1" quat="1.32679e-06 -1 0 0" type="mesh" rgba="0.231373 0.380392 0.705882 1" mesh="hipz12"/>
      <geom pos="-0.575896 0.0494047 -0.172196" quat="0.792907 -0.60316 -0.052417 -0.0689069" type="mesh" rgba="0.615686 0.811765 0.929412 1" mesh="robstride02"/>
      <geom pos="0 0 -0.1" quat="1.32679e-06 -1 0 0" type="mesh" rgba="0.647059 0.647059 0.647059 1" mesh="hipz22"/>
      
      <body name="hipy_subassembly" pos="-0.01897 -0.0289 -0.09689" quat="0.388857 0.132751 0.0879726 -0.907429">
        <inertial pos="0.00476547 -0.00266343 -0.0607297" quat="0.916918 -0.328471 -0.0265972 0.225082" mass="0.241618" diaginertia="0.000514846 0.000474201 0.00039973"/>
        <joint name="hipx_right" pos="0 0 0" axis="0 0 1" range="-3.14159 3.14159" actuatorfrcrange="-10 10"/>
        <geom type="mesh" rgba="0.647059 0.647059 0.647059 1" mesh="hipxy"/>
        
        <body name="tigh_subassembly" pos="0.012638 -0.0276823 -0.112055" quat="0.3075 0.0287184 0.729949 -0.609748">
          <inertial pos="0.0501976 0.0785779 -0.0353813" quat="0.64331 0.334215 -0.585819 0.362311" mass="2.5804" diaginertia="0.0237789 0.0223377 0.0035913"/>
          <joint name="hipy_right" pos="0 0 0" axis="0 0 1" range="-3.14159 3.14159" actuatorfrcrange="-10 10"/>
          <geom pos="0.210506 0.184547 -0.0305" quat="0.612371 0.612373 -0.353555 -0.353553" type="mesh" rgba="0.768627 0.886275 0.952941 1" mesh="knee_rod22"/>
          <geom pos="-0.437806 0.570998 -0.07" quat="0.683011 -0.683014 0.183013 -0.183012" type="mesh" rgba="0.647059 0.647059 0.647059 1" mesh="robstrideo3"/>
          <geom pos="0.210506 0.184547 -0.0305" quat="0.612371 0.612373 -0.353555 -0.353553" type="mesh" rgba="0.768627 0.886275 0.952941 1" mesh="knee_rod12"/>
          <geom pos="0.058 0.324459 -0.0305" quat="0.707105 0.707108 0 0" type="mesh" rgba="0.647059 0.647059 0.647059 1" mesh="knee_actuation"/>
          <geom pos="0.17 0.294449 -0.0305" quat="0.683011 0.683014 -0.183013 -0.183012" type="mesh" rgba="0.917647 0.917647 0.917647 1" mesh="femur_22" contype="1" conaffinity="1"  />
          <geom pos="0.17 0.294449 -0.0305" quat="0.683011 0.683014 -0.183013 -0.183012" type="mesh" rgba="0.615686 0.811765 0.929412 1" mesh="femur_12" contype="1" conaffinity="1"/>
          <geom pos="0 0 -0.0938" quat="0.183014 -0.683011 0.183014 0.683014" type="mesh" rgba="0.231373 0.380392 0.705882 1" mesh="part_3"/>
          <geom pos="-0.495806 0.470539 -0.0275" quat="0.683011 -0.683014 0.183013 -0.183012" type="mesh" rgba="0.647059 0.647059 0.647059 1" mesh="robstrideo3"/>
          
          <body name="shin_subassembly" pos="0.17 0.294449 -0.0305" quat="1.26691e-06 0.954863 -0.297046 -3.94118e-07">
            <inertial pos="-0.0754732 -0.0505369 6.35117e-05" quat="-0.234536 0.671141 0.137741 0.68963" mass="0.593267" diaginertia="0.00176325 0.00172799 0.000245834"/>
            <joint name="knee_right" pos="0 0 0" axis="0 0 1" range="-3.14159 3.14159" actuatorfrcrange="-10 10"/>
            <geom pos="-0.304936 0.362963 0.019" quat="0.620646 0.620648 -0.338818 -0.338816" type="mesh" rgba="0.980392 0.713725 0.00392157 1" mesh="rmdx43"/>
            <geom pos="-0.218697 -0.140611 0.019" quat="0.620646 -0.620648 0.338818 -0.338816" type="mesh" rgba="0.647059 0.647059 0.647059 1" mesh="tibias22"/>
            <geom pos="-0.0331382 0.124911 -0.019" quat="0.706617 0.706619 -0.0262877 -0.0262876" type="mesh" rgba="0.231373 0.380392 0.705882 1" mesh="actuation_ankle"/>
            <geom pos="-0.349517 0.3343 0.006" quat="0.620646 0.620648 -0.338818 -0.338816" type="mesh" rgba="0.980392 0.713725 0.00392157 1" mesh="rmdx43"/>
            <geom pos="-0.218697 -0.140611 0.019" quat="0.620646 -0.620648 0.338818 -0.338816" type="mesh" rgba="0.615686 0.811765 0.929412 1" mesh="tibias12"/>
            <geom pos="-0.100604 -0.2109 0.019" quat="0.706617 -0.706619 0.0262877 -0.0262876" type="mesh" rgba="0.231373 0.380392 0.705882 1" mesh="actuation_ankle"/>
            
            <body name="ankle_subassembly" pos="-0.211522 -0.151191 0.02" quat="1.10817e-06 0.835222 0.549913 7.29622e-07">
              <inertial pos="-1.62086e-08 -0.000727483 0.02" mass="0.0168168" diaginertia="5.19458e-06 4.86353e-06 8.35665e-07"/>
              <joint name="ankley_right" pos="0 0 0" axis="0 0 1" range="-3.14159 3.14159" actuatorfrcrange="-10 10" armature="0.02"/>
              <geom pos="0 0 0.0195" quat="9.38184e-07 0.707105 9.38187e-07 -0.707108" type="mesh" rgba="0.231373 0.380392 0.705882 1" mesh="part_3"/>
              
              <body name="foot_subassembly" pos="0 -0.01594 0.02" quat="0.499998 0.5 0.5 -0.500002">
                <inertial pos="8.52312e-09 -0.0138418 -0.052232" quat="0.705627 0.0421767 -0.042203 0.706067" mass="0.122498" diaginertia="0.000163602 0.000163413 6.9433e-05"/>
                <joint name="anklex_right" pos="0 0 0" axis="0 0 1" range="-3.14159 3.14159" actuatorfrcrange="-10 10" armature="0.02"/>
                <geom pos="0 -0.035 -0.0385" quat="0.499998 -0.5 -0.5 -0.500002" type="mesh" rgba="0.498039 0.498039 0.498039 1" mesh="foot" contype="1" conaffinity="1"/>
              </body>
            </body>
          </body>
        </body>
      </body>
    </body>
    <body name="hipx_subassemby_sym" pos="-0.000819037 0.13316 0.04164" quat="0.826606 -0.0574677 0.0409287 0.558341">
      <inertial pos="-0.0179432 0.0274245 -0.0837272" quat="0.424685 0.401162 -0.212175 0.783386" mass="0.794016" diaginertia="0.0011506 0.000967878 0.000726822"/>
      <joint name="hipz_left" pos="0 0 0" axis="0 0 1" range="-3.14159 3.14159" actuatorfrcrange="-10 10"/>
      <geom pos="-0.575896 0.057308 -0.20175" quat="0.603161 -0.792907 -0.068907 -0.0524169" type="mesh" rgba="0.615686 0.811765 0.929412 1" mesh="robstride02"/>
      <geom pos="0 0 0.1" quat="1 0 0 0" type="mesh" rgba="0.231373 0.380392 0.705882 1" mesh="hipz22_sym"/>
      <geom pos="0 0 0.1" quat="1 0 0 0" type="mesh" rgba="0.647059 0.647059 0.647059 1" mesh="hipz12_sym"/>
      
      <body name="hipy_subassembly_sym" pos="-0.01897 0.0289 -0.09689" quat="0.379002 -0.131789 0.0894063 0.91159">
        <inertial pos="0.0047654 0.00266393 -0.0607296" quat="0.916914 0.328483 -0.0266015 -0.225077" mass="0.241619" diaginertia="0.000514848 0.000474202 0.000399736"/>
        <joint name="hipx_left" pos="0 0 0" axis="0 0 1" range="-3.14159 3.14159" actuatorfrcrange="-10 10"/>
        <geom quat="1.32679e-06 -1 0 0" type="mesh" rgba="0.647059 0.647059 0.647059 1" mesh="hipxy_sym"/>
        
        <body name="tigh_subassembly_sym" pos="0.012638 0.0276823 -0.112055" quat="-0.0382843 0.339833 0.646657 0.681823">
          <inertial pos="-0.0431321 -0.0830741 -0.0353867" quat="0.584181 0.376186 -0.634805 0.337993" mass="2.5804" diaginertia="0.0240047 0.0225643 0.00359599"/>
          <joint name="hipy_left" pos="0 0 0" axis="0 0 1" range="-3.14159 3.14159" actuatorfrcrange="-10 10"/>
          <geom pos="-0.058 -0.280519 0.0295" quat="0.707105 -0.707108 0 0" type="mesh" rgba="0.768627 0.886275 0.952941 1" mesh="knee_rod22_sym"/>
          <geom pos="0 0 -0.0938" quat="0.683011 0.183012 0.683014 -0.183013" type="mesh" rgba="0.231373 0.380392 0.705882 1" mesh="part_3"/>
          <geom pos="-0.17 -0.294449 0.0295" quat="0.683011 -0.683014 0.183013 -0.183012" type="mesh" rgba="0.615686 0.811765 0.929412 1" mesh="femur_12_sym" contype="1" conaffinity="1"/>
          <geom pos="-0.058 0.123541 -0.0305" quat="0.707105 0.707108 0 0" type="mesh" rgba="0.647059 0.647059 0.647059 1" mesh="knee_actuation"/>
          <geom pos="-0.17 -0.294449 0.0295" quat="0.683011 -0.683014 0.183013 -0.183012" type="mesh" rgba="0.917647 0.917647 0.917647 1" mesh="femur_22_sym" contype="1" conaffinity="1"/>
          <geom pos="0.655402 -0.194111 -0.0025" quat="0.183014 0.183014 0.683014 0.683011" type="mesh" rgba="0.647059 0.647059 0.647059 1" mesh="robstrideo3"/>
          <geom pos="-0.058 -0.280519 0.0295" quat="0.707105 -0.707108 0 0" type="mesh" rgba="0.768627 0.886275 0.952941 1" mesh="knee_rod12_sym"/>
          <geom pos="0.597402 -0.29457 -0.045" quat="0.183014 0.183014 0.683014 0.683011" type="mesh" rgba="0.647059 0.647059 0.647059 1" mesh="robstrideo3"/>
          
          <body name="shin_subassembly_sym" pos="-0.17 -0.294449 -0.0305" quat="0.766698 0 0 -0.642008">
            <inertial pos="0.00142213 -0.0907873 -1.51262e-05" quat="0.519893 0.470365 -0.498299 0.510065" mass="0.593266" diaginertia="0.00176327 0.00173466 0.000237587"/>
            <joint name="knee_left" pos="0 0 0" axis="0 0 1" range="-3.14159 3.14159" actuatorfrcrange="-10 10"/>
            <geom pos="0 -0.26 0.067" quat="0.707105 -0.707108 0 0" type="mesh" rgba="0.615686 0.811765 0.929412 1" mesh="tibias12_sym"/>
            <geom pos="0.12299 -0.14568 0.0195" quat="0.632813 -0.632815 -0.31551 0.315509" type="mesh" rgba="0.231373 0.380392 0.705882 1" mesh="actuation_ankle"/>
            <geom pos="0.470217 -0.113201 -0.006" quat="9.38184e-07 -9.38187e-07 0.707108 -0.707105" type="mesh" rgba="0.980392 0.713725 0.00392157 1" mesh="rmdx43"/>
            <geom pos="0.470217 -0.0457991 0.006" quat="9.38184e-07 9.38187e-07 -0.707108 -0.707105" type="mesh" rgba="0.980392 0.713725 0.00392157 1" mesh="rmdx43"/>
            <geom pos="0 -0.26 0.067" quat="0.707105 -0.707108 0 0" type="mesh" rgba="0.647059 0.647059 0.647059 1" mesh="tibias22_sym"/>
            <geom pos="-0.12299 -0.0133205 -0.0195" quat="0.632813 0.632815 0.31551 0.315509" type="mesh" rgba="0.231373 0.380392 0.705882 1" mesh="actuation_ankle"/>
            
            <body name="ankle_subassembly_2" pos="0 -0.26 -0.02" quat="0.87107 0 0 -0.491159">
              <inertial pos="1.62086e-08 -0.000727483 0.02" mass="0.0168168" diaginertia="5.19458e-06 4.86353e-06 8.35665e-07"/>
              <joint name="ankley_left" pos="0 0 0" axis="0 0 1" range="-3.14159 3.14159" actuatorfrcrange="-10 10" armature="0.02"/>
              <geom pos="0 0 0.02" quat="9.38184e-07 -0.707105 -9.38187e-07 -0.707108" type="mesh" rgba="0.615686 0.811765 0.929412 1" mesh="ujoint"/>
              <geom pos="0 0 0.0205" quat="9.38184e-07 -0.707105 -9.38187e-07 -0.707108" type="mesh" rgba="0.231373 0.380392 0.705882 1" mesh="part_3"/>
              <geom pos="0 0 0.0195" quat="9.38184e-07 0.707105 9.38187e-07 -0.707108" type="mesh" rgba="0.231373 0.380392 0.705882 1" mesh="part_3"/>
              
              <body name="foot_subassembly_2" pos="0 -0.01594 0.02" quat="0.50166 0.501662 -0.498332 0.498334">
                <inertial pos="8.52312e-09 -0.0138418 -0.052232" quat="0.705627 0.0421767 -0.042203 0.706067" mass="0.122498" diaginertia="0.000163602 0.000163413 6.9433e-05"/>
                <joint name="anklex_left" pos="0 0 0" axis="0 0 1" range="-3.14159 3.14159" actuatorfrcrange="-10 10" armature="0.02"/>
                <geom pos="0 -0.035 -0.0385" quat="0.499998 -0.5 -0.5 -0.500002" type="mesh" rgba="0.498039 0.498039 0.498039 1" mesh="foot" contype="1" conaffinity="1"/>
              </body>
            </body>
          </body>
        </body>
      </body>
    </body>
    </body>
  </worldbody>
  
  
  <actuator>
  <position name="m_hip_z_right"   joint="hipz_right"        kp="20" kv="2" gear="1" ctrlrange="-1 1"/>
  <position name="m_hip_x_right"  joint="hipx_right"         kp="20" kv="2" gear="1" ctrlrange="-1 1"/>
  <position name="m_hip_y_right" joint="hipy_right"          kp="100" kv="2" gear="1" ctrlrange="-1 1"/>
  <position name="m_knee_right"      joint="knee_right"      kp="100" kv="2"  gear="1" ctrlrange="-1 1"/>
  <position name="m_ankley_right"     joint="ankley_right"   kp="40" kv="2"  gear="1"  ctrlrange="-1 1"/>
  <position name="m_anklex_right"     joint="anklex_right"   kp="10" kv="2"  gear="1"  ctrlrange="-1 1"/>
  <position name="m_hip_z_left"   joint="hipz_left"          kp="20" kv="2" gear="1" ctrlrange="-1 1"/>
  <position name="m_hip_x_left"  joint="hipx_left"           kp="20" kv="2" gear="1" ctrlrange="-1 1"/>
  <position name="m_hip_y_left" joint="hipy_left"            kp="100" kv="2" gear="1" ctrlrange="-1 1"/>
  <position name="m_knee_left"      joint="knee_left"        kp="100" kv="2" gear="1" ctrlrange="-1 1"/>
  <position name="m_ankley_left"     joint="ankley_left"     kp="40" kv="2" gear="1"  ctrlrange="-1 1"/>
  <position name="m_anklex_left"     joint="anklex_left"     kp="10" kv="2" gear="1"  ctrlrange="-1 1"/>
</actuator>
</mujoco>
